<?xml version="1.0"?>
<robot name="hospital_robot">

  <!-- ============================================================ -->
  <!-- MATERIALS (for RViz / Gazebo visualization)                   -->
  <!-- ============================================================ -->
  <material name="body_blue">
    <color rgba="0.2 0.3 0.8 1.0"/>
  </material>
  <material name="wheel_black">
    <color rgba="0.1 0.1 0.1 1.0"/>
  </material>
  <material name="sensor_grey">
    <color rgba="0.6 0.6 0.6 1.0"/>
  </material>
  <material name="camera_dark">
    <color rgba="0.05 0.05 0.05 1.0"/>
  </material>

  <!-- ============================================================ -->
  <!-- BASE LINK                                                      -->
  <!-- Main chassis: 0.5 x 0.4 x 0.2 m box                            -->
  <!-- ============================================================ -->
  <link name="base_link">
    <visual>
      <origin xyz="0 0 0" rpy="0 0 0"/>
      <geometry>
        <box size="0.5 0.4 0.2"/>
      </geometry>
      <material name="body_blue"/>
    </visual>
    <collision>
      <origin xyz="0 0 0" rpy="0 0 0"/>
      <geometry>
        <box size="0.5 0.4 0.2"/>
      </geometry>
    </collision>
    <inertial>
      <mass value="5.0"/>
      <origin xyz="0 0 0"/>
      <inertia ixx="0.05" ixy="0.0" ixz="0.0"
               iyy="0.06" iyz="0.0"
               izz="0.08"/>
    </inertial>
  </link>

  <!-- ============================================================ -->
  <!-- LEFT WHEEL                                                     -->
  <!-- Cylinder: radius 0.08 m, length 0.04 m                         -->
  <!-- ============================================================ -->
  <link name="left_wheel">
    <visual>
      <origin xyz="0 0 0" rpy="1.5708 0 0"/>
      <geometry>
        <cylinder radius="0.08" length="0.04"/>
      </geometry>
      <material name="wheel_black"/>
    </visual>
    <collision>
      <origin xyz="0 0 0" rpy="1.5708 0 0"/>
      <geometry>
        <cylinder radius="0.08" length="0.04"/>
      </geometry>
    </collision>
    <inertial>
      <mass value="0.5"/>
      <origin xyz="0 0 0"/>
      <inertia ixx="0.001" ixy="0.0" ixz="0.0"
               iyy="0.001" iyz="0.0"
               izz="0.001"/>
    </inertial>
  </link>

  <!-- Left wheel joint
       Note: type set to "continuous" so the wheel can rotate.
       This is required for the diff-drive plugin below to move
       the robot. If you need a purely static description,
       change type to "fixed". -->
  <joint name="left_wheel_joint" type="continuous">
    <parent link="base_link"/>
    <child link="left_wheel"/>
    <origin xyz="0.0 0.22 -0.02" rpy="0 0 0"/>
    <axis xyz="0 1 0"/>
  </joint>

  <!-- ============================================================ -->
  <!-- RIGHT WHEEL                                                    -->
  <!-- Cylinder: radius 0.08 m, length 0.04 m                         -->
  <!-- ============================================================ -->
  <link name="right_wheel">
    <visual>
      <origin xyz="0 0 0" rpy="1.5708 0 0"/>
      <geometry>
        <cylinder radius="0.08" length="0.04"/>
      </geometry>
      <material name="wheel_black"/>
    </visual>
    <collision>
      <origin xyz="0 0 0" rpy="1.5708 0 0"/>
      <geometry>
        <cylinder radius="0.08" length="0.04"/>
      </geometry>
    </collision>
    <inertial>
      <mass value="0.5"/>
      <origin xyz="0 0 0"/>
      <inertia ixx="0.001" ixy="0.0" ixz="0.0"
               iyy="0.001" iyz="0.0"
               izz="0.001"/>
    </inertial>
  </link>

  <joint name="right_wheel_joint" type="continuous">
    <parent link="base_link"/>
    <child link="right_wheel"/>
    <origin xyz="0.0 -0.22 -0.02" rpy="0 0 0"/>
    <axis xyz="0 1 0"/>
  </joint>

  <!-- ============================================================ -->
  <!-- CASTER / SUPPORT WHEELS (fixed, simple skid support)           -->
  <!-- Small spheres front and back so the chassis stays level        -->
  <!-- ============================================================ -->
  <link name="front_caster">
    <visual>
      <geometry>
        <sphere radius="0.05"/>
      </geometry>
      <material name="wheel_black"/>
    </visual>
    <collision>
      <geometry>
        <sphere radius="0.05"/>
      </geometry>
    </collision>
    <inertial>
      <mass value="0.1"/>
      <origin xyz="0 0 0"/>
      <inertia ixx="0.0001" ixy="0.0" ixz="0.0"
               iyy="0.0001" iyz="0.0"
               izz="0.0001"/>
    </inertial>
  </link>

  <joint name="front_caster_joint" type="fixed">
    <parent link="base_link"/>
    <child link="front_caster"/>
    <origin xyz="0.2 0 -0.05" rpy="0 0 0"/>
  </joint>

  <link name="rear_caster">
    <visual>
      <geometry>
        <sphere radius="0.05"/>
      </geometry>
      <material name="wheel_black"/>
    </visual>
    <collision>
      <geometry>
        <sphere radius="0.05"/>
      </geometry>
    </collision>
    <inertial>
      <mass value="0.1"/>
      <origin xyz="0 0 0"/>
      <inertia ixx="0.0001" ixy="0.0" ixz="0.0"
               iyy="0.0001" iyz="0.0"
               izz="0.0001"/>
    </inertial>
  </link>

  <joint name="rear_caster_joint" type="fixed">
    <parent link="base_link"/>
    <child link="rear_caster"/>
    <origin xyz="-0.2 0 -0.05" rpy="0 0 0"/>
  </joint>

  <!-- ============================================================ -->
  <!-- LIDAR LINK                                                     -->
  <!-- Mounted on top-center of the chassis                          -->
  <!-- Cylinder: radius 0.05 m, length 0.06 m                         -->
  <!-- ============================================================ -->
  <link name="lidar_link">
    <visual>
      <origin xyz="0 0 0" rpy="0 0 0"/>
      <geometry>
        <cylinder radius="0.05" length="0.06"/>
      </geometry>
      <material name="sensor_grey"/>
    </visual>
    <collision>
      <origin xyz="0 0 0" rpy="0 0 0"/>
      <geometry>
        <cylinder radius="0.05" length="0.06"/>
      </geometry>
    </collision>
    <inertial>
      <mass value="0.2"/>
      <origin xyz="0 0 0"/>
      <inertia ixx="0.0002" ixy="0.0" ixz="0.0"
               iyy="0.0002" iyz="0.0"
               izz="0.0002"/>
    </inertial>
  </link>

  <!-- Fixed joint: lidar mounted on top-center of base_link -->
  <joint name="lidar_joint" type="fixed">
    <parent link="base_link"/>
    <child link="lidar_link"/>
    <origin xyz="0 0 0.13" rpy="0 0 0"/>
  </joint>

  <!-- ============================================================ -->
  <!-- CAMERA LINK                                                    -->
  <!-- Mounted on the front-top of the chassis                        -->
  <!-- Box: 0.05 x 0.05 x 0.05 m                                       -->
  <!-- ============================================================ -->
  <link name="camera_link">
    <visual>
      <origin xyz="0 0 0" rpy="0 0 0"/>
      <geometry>
        <box size="0.05 0.05 0.05"/>
      </geometry>
      <material name="camera_dark"/>
    </visual>
    <collision>
      <origin xyz="0 0 0" rpy="0 0 0"/>
      <geometry>
        <box size="0.05 0.05 0.05"/>
      </geometry>
    </collision>
    <inertial>
      <mass value="0.05"/>
      <origin xyz="0 0 0"/>
      <inertia ixx="0.00005" ixy="0.0" ixz="0.0"
               iyy="0.00005" iyz="0.0"
               izz="0.00005"/>
    </inertial>
  </link>

  <!-- Fixed joint: camera mounted on the front-top of base_link -->
  <joint name="camera_joint" type="fixed">
    <parent link="base_link"/>
    <child link="camera_link"/>
    <origin xyz="0.22 0 0.08" rpy="0 0 0"/>
  </joint>

  <!-- ============================================================ -->
  <!-- GAZEBO PLUGINS (ROS 2 Jazzy + Gazebo Harmonic / ros_gz)        -->
  <!-- ============================================================ -->

  <!-- Differential drive plugin -->
  <gazebo>
    <plugin filename="gz-sim-diff-drive-system"
            name="gz::sim::systems::DiffDrive">
      <left_joint>left_wheel_joint</left_joint>
      <right_joint>right_wheel_joint</right_joint>
      <wheel_separation>0.44</wheel_separation>
      <wheel_radius>0.08</wheel_radius>
      <odom_publish_frequency>30</odom_publish_frequency>
      <topic>cmd_vel</topic>
      <odom_topic>odom</odom_topic>
      <frame_id>odom</frame_id>
      <child_frame_id>base_link</child_frame_id>
    </plugin>
  </gazebo>

  <!-- Joint state publisher plugin -->
  <gazebo>
    <plugin filename="gz-sim-joint-state-publisher-system"
            name="gz::sim::systems::JointStatePublisher">
    </plugin>
  </gazebo>

  <!-- 2D LiDAR sensor on lidar_link -->
  <gazebo reference="lidar_link">
    <sensor name="lidar_sensor" type="gpu_lidar">
      <pose>0 0 0 0 0 0</pose>
      <topic>scan</topic>
      <update_rate>10</update_rate>
      <lidar>
        <scan>
          <horizontal>
            <samples>360</samples>
            <resolution>1</resolution>
            <min_angle>-3.14159</min_angle>
            <max_angle>3.14159</max_angle>
          </horizontal>
        </scan>
        <range>
          <min>0.12</min>
          <max>10.0</max>
          <resolution>0.01</resolution>
        </range>
      </lidar>
      <always_on>true</always_on>
      <visualize>true</visualize>
    </sensor>
  </gazebo>

  <!-- Camera sensor on camera_link -->
  <gazebo reference="camera_link">
    <sensor name="camera_sensor" type="camera">
      <pose>0 0 0 0 0 0</pose>
      <topic>camera/image_raw</topic>
      <update_rate>30</update_rate>
      <camera>
        <horizontal_fov>1.047</horizontal_fov>
        <image>
          <width>640</width>
          <height>480</height>
          <format>R8G8B8</format>
        </image>
        <clip>
          <near>0.05</near>
          <far>20.0</far>
        </clip>
      </camera>
      <always_on>true</always_on>
      <visualize>true</visualize>
    </sensor>
  </gazebo>

</robot>